[I 16:00:00.536 NotebookApp] The port 8888 is already in use, trying another port.
[I 16:00:00.537 NotebookApp] The port 8889 is already in use, trying another port.
[I 16:00:00.537 NotebookApp] Serving notebooks from local directory: /Users/blacc/Documents/machine-learning
[I 16:00:00.537 NotebookApp] Jupyter Notebook 6.4.12 is running at:
[I 16:00:00.537 NotebookApp] http://localhost:8890/?token=b0d6dfb3d0647a89ab14b9d8be75f05aa99eeac8fe67b2c0
[I 16:00:00.538 NotebookApp]  or http://127.0.0.1:8890/?token=b0d6dfb3d0647a89ab14b9d8be75f05aa99eeac8fe67b2c0
[I 16:00:00.538 NotebookApp] Use Control-C to stop this server and shut down all kernels (twice to skip confirmation).
[C 16:00:00.541 NotebookApp] 
    
    To access the notebook, open this file in a browser:
        file:///Users/blacc/Library/Jupyter/runtime/nbserver-35786-open.html
    Or copy and paste one of these URLs:
        http://localhost:8890/?token=b0d6dfb3d0647a89ab14b9d8be75f05aa99eeac8fe67b2c0
     or http://127.0.0.1:8890/?token=b0d6dfb3d0647a89ab14b9d8be75f05aa99eeac8fe67b2c0
[W 16:00:04.527 NotebookApp] Notebook hello-world.ipynb is not trusted
[I 16:00:04.627 NotebookApp] Kernel started: 57c73bed-fdf6-49f8-8e2c-b317ab5f4d7e, name: python3
[I 16:02:04.595 NotebookApp] Saving file at /hello-world.ipynb
[I 16:04:04.624 NotebookApp] Saving file at /hello-world.ipynb
[I 16:06:04.639 NotebookApp] Saving file at /hello-world.ipynb
[I 16:08:04.637 NotebookApp] Saving file at /hello-world.ipynb
[I 16:10:04.629 NotebookApp] Saving file at /hello-world.ipynb
[I 16:12:04.642 NotebookApp] Saving file at /hello-world.ipynb
[I 16:14:04.672 NotebookApp] Saving file at /hello-world.ipynb
Metal device set to: Apple M1
2022-07-31 16:15:57.755538: I tensorflow/core/common_runtime/pluggable_device/pluggable_device_factory.cc:305] Could not identify NUMA node of platform GPU ID 0, defaulting to 0. Your kernel may not have been built with NUMA support.
2022-07-31 16:15:57.755874: I tensorflow/core/common_runtime/pluggable_device/pluggable_device_factory.cc:271] Created TensorFlow device (/job:localhost/replica:0/task:0/device:GPU:0 with 0 MB memory) -> physical PluggableDevice (device: 0, name: METAL, pci bus id: <undefined>)
[I 16:16:04.686 NotebookApp] Saving file at /hello-world.ipynb
[I 16:20:24.964 NotebookApp] Creating new notebook in 
[I 16:20:25.640 NotebookApp] Kernel started: 4f20fb6d-1b7b-4f11-b1fd-e87feb4f920a, name: python3
[I 16:22:25.657 NotebookApp] Saving file at /Untitled.ipynb
[I 16:24:04.780 NotebookApp] Saving file at /hello-world.ipynb
2022-07-31 16:24:59.585082: W tensorflow/core/platform/profile_utils/cpu_utils.cc:128] Failed to get CPU frequency: 0 Hz
2022-07-31 16:24:59.749695: I tensorflow/core/grappler/optimizers/custom_graph_optimizer_registry.cc:113] Plugin optimizer for device_type GPU is enabled.
[I 16:26:04.814 NotebookApp] Saving file at /hello-world.ipynb
2022-07-31 16:28:01.947975: I tensorflow/core/grappler/optimizers/custom_graph_optimizer_registry.cc:113] Plugin optimizer for device_type GPU is enabled.
[I 16:28:04.837 NotebookApp] Saving file at /hello-world.ipynb
[W 16:29:59.086 NotebookApp] Notebook Untitled.ipynb is not trusted
[W 16:30:20.367 NotebookApp] Notebook Untitled.ipynb is not trusted
[I 16:37:28.568 NotebookApp] Kernel shutdown: 4f20fb6d-1b7b-4f11-b1fd-e87feb4f920a
[I 16:37:28.571 NotebookApp] Kernel shutdown: 57c73bed-fdf6-49f8-8e2c-b317ab5f4d7e
[I 16:37:29.051 NotebookApp] Starting buffering for 57c73bed-fdf6-49f8-8e2c-b317ab5f4d7e:76f6cbd140aa4baf8a6f3cf823bbb391
[I 16:37:29.059 NotebookApp] Kernel shutdown: 57c73bed-fdf6-49f8-8e2c-b317ab5f4d7e
[E 16:37:29.060 NotebookApp] Uncaught exception DELETE /api/sessions/5b39355d-5da9-4736-b422-6616bb6b8393 (::1)
    HTTPServerRequest(protocol='http', host='localhost:8890', method='DELETE', uri='/api/sessions/5b39355d-5da9-4736-b422-6616bb6b8393', version='HTTP/1.1', remote_ip='::1')
    Traceback (most recent call last):
      File "/Users/blacc/miniconda3/lib/python3.9/site-packages/tornado/web.py", line 1704, in _execute
        result = await result
      File "/Users/blacc/miniconda3/lib/python3.9/site-packages/tornado/gen.py", line 769, in run
        yielded = self.gen.throw(*exc_info)  # type: ignore
      File "/Users/blacc/miniconda3/lib/python3.9/site-packages/notebook/services/sessions/handlers.py", line 164, in delete
        yield maybe_future(sm.delete_session(session_id))
      File "/Users/blacc/miniconda3/lib/python3.9/site-packages/tornado/gen.py", line 762, in run
        value = future.result()
      File "/Users/blacc/miniconda3/lib/python3.9/site-packages/tornado/gen.py", line 775, in run
        yielded = self.gen.send(value)
      File "/Users/blacc/miniconda3/lib/python3.9/site-packages/notebook/services/sessions/sessionmanager.py", line 287, in delete_session
        yield maybe_future(self.kernel_manager.shutdown_kernel(session['kernel']['id']))
      File "/Users/blacc/miniconda3/lib/python3.9/site-packages/notebook/services/kernels/kernelmanager.py", line 304, in shutdown_kernel
        self.pinned_superclass.shutdown_kernel(self, kernel_id, now=now, restart=restart)
      File "/Users/blacc/miniconda3/lib/python3.9/site-packages/jupyter_client/utils.py", line 26, in wrapped
        raise e
      File "/Users/blacc/miniconda3/lib/python3.9/site-packages/jupyter_client/utils.py", line 23, in wrapped
        return loop.run_until_complete(future)
      File "/Users/blacc/miniconda3/lib/python3.9/site-packages/nest_asyncio.py", line 89, in run_until_complete
        return f.result()
      File "/Users/blacc/miniconda3/lib/python3.9/asyncio/futures.py", line 201, in result
        raise self._exception
      File "/Users/blacc/miniconda3/lib/python3.9/asyncio/tasks.py", line 256, in __step
        result = coro.send(None)
      File "/Users/blacc/miniconda3/lib/python3.9/site-packages/jupyter_client/multikernelmanager.py", line 274, in _async_shutdown_kernel
        if km.ready.exception():
    asyncio.exceptions.InvalidStateError: Exception is not set.
[W 16:37:29.069 NotebookApp] Unhandled error
[E 16:37:29.070 NotebookApp] {
      "Host": "localhost:8890",
      "Accept": "application/json, text/javascript, */*; q=0.01",
      "Referer": "http://localhost:8890/notebooks/hello-world.ipynb",
      "User-Agent": "Mozilla/5.0 (Macintosh; Intel Mac OS X 10_15_7) AppleWebKit/605.1.15 (KHTML, like Gecko) Version/15.6 Safari/605.1.15"
    }
[E 16:37:29.070 NotebookApp] 500 DELETE /api/sessions/5b39355d-5da9-4736-b422-6616bb6b8393 (::1) 11.760000ms referer=http://localhost:8890/notebooks/hello-world.ipynb
[I 16:37:31.341 NotebookApp] Kernel shutdown: 4f20fb6d-1b7b-4f11-b1fd-e87feb4f920a
[E 16:37:31.342 NotebookApp] Uncaught exception DELETE /api/sessions/ee6b332e-6aef-4679-b18b-ceae95de25a5 (::1)
    HTTPServerRequest(protocol='http', host='localhost:8890', method='DELETE', uri='/api/sessions/ee6b332e-6aef-4679-b18b-ceae95de25a5', version='HTTP/1.1', remote_ip='::1')
    Traceback (most recent call last):
      File "/Users/blacc/miniconda3/lib/python3.9/site-packages/tornado/web.py", line 1704, in _execute
        result = await result
      File "/Users/blacc/miniconda3/lib/python3.9/site-packages/tornado/gen.py", line 769, in run
        yielded = self.gen.throw(*exc_info)  # type: ignore
      File "/Users/blacc/miniconda3/lib/python3.9/site-packages/notebook/services/sessions/handlers.py", line 164, in delete
        yield maybe_future(sm.delete_session(session_id))
      File "/Users/blacc/miniconda3/lib/python3.9/site-packages/tornado/gen.py", line 762, in run
        value = future.result()
      File "/Users/blacc/miniconda3/lib/python3.9/site-packages/tornado/gen.py", line 775, in run
        yielded = self.gen.send(value)
      File "/Users/blacc/miniconda3/lib/python3.9/site-packages/notebook/services/sessions/sessionmanager.py", line 287, in delete_session
        yield maybe_future(self.kernel_manager.shutdown_kernel(session['kernel']['id']))
      File "/Users/blacc/miniconda3/lib/python3.9/site-packages/notebook/services/kernels/kernelmanager.py", line 304, in shutdown_kernel
        self.pinned_superclass.shutdown_kernel(self, kernel_id, now=now, restart=restart)
      File "/Users/blacc/miniconda3/lib/python3.9/site-packages/jupyter_client/utils.py", line 26, in wrapped
        raise e
      File "/Users/blacc/miniconda3/lib/python3.9/site-packages/jupyter_client/utils.py", line 23, in wrapped
        return loop.run_until_complete(future)
      File "/Users/blacc/miniconda3/lib/python3.9/site-packages/nest_asyncio.py", line 89, in run_until_complete
        return f.result()
      File "/Users/blacc/miniconda3/lib/python3.9/asyncio/futures.py", line 201, in result
        raise self._exception
      File "/Users/blacc/miniconda3/lib/python3.9/asyncio/tasks.py", line 256, in __step
        result = coro.send(None)
      File "/Users/blacc/miniconda3/lib/python3.9/site-packages/jupyter_client/multikernelmanager.py", line 274, in _async_shutdown_kernel
        if km.ready.exception():
    asyncio.exceptions.InvalidStateError: Exception is not set.
[W 16:37:31.342 NotebookApp] Unhandled error
[E 16:37:31.342 NotebookApp] {
      "Host": "localhost:8890",
      "Accept": "application/json, text/javascript, */*; q=0.01",
      "Referer": "http://localhost:8890/notebooks/Untitled.ipynb?kernel_name=python3",
      "User-Agent": "Mozilla/5.0 (Macintosh; Intel Mac OS X 10_15_7) AppleWebKit/605.1.15 (KHTML, like Gecko) Version/15.6 Safari/605.1.15"
    }
[E 16:37:31.342 NotebookApp] 500 DELETE /api/sessions/ee6b332e-6aef-4679-b18b-ceae95de25a5 (::1) 3.460000ms referer=http://localhost:8890/notebooks/Untitled.ipynb?kernel_name=python3
[I 16:37:31.343 NotebookApp] Starting buffering for 4f20fb6d-1b7b-4f11-b1fd-e87feb4f920a:e792ac5769664efe9a1eb26aee6f1ba4
[I 16:37:31.345 NotebookApp] Kernel shutdown: 4f20fb6d-1b7b-4f11-b1fd-e87feb4f920a
[I 16:37:31.345 NotebookApp] Kernel shutdown: 4f20fb6d-1b7b-4f11-b1fd-e87feb4f920a
[E 16:37:31.345 NotebookApp] Uncaught exception DELETE /api/sessions/ee6b332e-6aef-4679-b18b-ceae95de25a5 (::1)
    HTTPServerRequest(protocol='http', host='localhost:8890', method='DELETE', uri='/api/sessions/ee6b332e-6aef-4679-b18b-ceae95de25a5', version='HTTP/1.1', remote_ip='::1')
    Traceback (most recent call last):
      File "/Users/blacc/miniconda3/lib/python3.9/site-packages/tornado/web.py", line 1704, in _execute
        result = await result
      File "/Users/blacc/miniconda3/lib/python3.9/site-packages/tornado/gen.py", line 769, in run
        yielded = self.gen.throw(*exc_info)  # type: ignore
      File "/Users/blacc/miniconda3/lib/python3.9/site-packages/notebook/services/sessions/handlers.py", line 164, in delete
        yield maybe_future(sm.delete_session(session_id))
      File "/Users/blacc/miniconda3/lib/python3.9/site-packages/tornado/gen.py", line 762, in run
        value = future.result()
      File "/Users/blacc/miniconda3/lib/python3.9/site-packages/tornado/gen.py", line 775, in run
        yielded = self.gen.send(value)
      File "/Users/blacc/miniconda3/lib/python3.9/site-packages/notebook/services/sessions/sessionmanager.py", line 287, in delete_session
        yield maybe_future(self.kernel_manager.shutdown_kernel(session['kernel']['id']))
      File "/Users/blacc/miniconda3/lib/python3.9/site-packages/notebook/services/kernels/kernelmanager.py", line 304, in shutdown_kernel
        self.pinned_superclass.shutdown_kernel(self, kernel_id, now=now, restart=restart)
      File "/Users/blacc/miniconda3/lib/python3.9/site-packages/jupyter_client/utils.py", line 26, in wrapped
        raise e
      File "/Users/blacc/miniconda3/lib/python3.9/site-packages/jupyter_client/utils.py", line 23, in wrapped
        return loop.run_until_complete(future)
      File "/Users/blacc/miniconda3/lib/python3.9/site-packages/nest_asyncio.py", line 89, in run_until_complete
        return f.result()
      File "/Users/blacc/miniconda3/lib/python3.9/asyncio/futures.py", line 201, in result
        raise self._exception
      File "/Users/blacc/miniconda3/lib/python3.9/asyncio/tasks.py", line 256, in __step
        result = coro.send(None)
      File "/Users/blacc/miniconda3/lib/python3.9/site-packages/jupyter_client/multikernelmanager.py", line 274, in _async_shutdown_kernel
        if km.ready.exception():
    asyncio.exceptions.InvalidStateError: Exception is not set.
[W 16:37:31.345 NotebookApp] Unhandled error
[E 16:37:31.346 NotebookApp] {
      "Host": "localhost:8890",
      "Accept": "application/json, text/javascript, */*; q=0.01",
      "Referer": "http://localhost:8890/notebooks/device_check.ipynb",
      "User-Agent": "Mozilla/5.0 (Macintosh; Intel Mac OS X 10_15_7) AppleWebKit/605.1.15 (KHTML, like Gecko) Version/15.6 Safari/605.1.15"
    }
[E 16:37:31.346 NotebookApp] 500 DELETE /api/sessions/ee6b332e-6aef-4679-b18b-ceae95de25a5 (::1) 1.610000ms referer=http://localhost:8890/notebooks/device_check.ipynb
[E 16:37:31.346 NotebookApp] Uncaught exception DELETE /api/sessions/ee6b332e-6aef-4679-b18b-ceae95de25a5 (::1)
    HTTPServerRequest(protocol='http', host='localhost:8890', method='DELETE', uri='/api/sessions/ee6b332e-6aef-4679-b18b-ceae95de25a5', version='HTTP/1.1', remote_ip='::1')
    Traceback (most recent call last):
      File "/Users/blacc/miniconda3/lib/python3.9/site-packages/tornado/web.py", line 1704, in _execute
        result = await result
      File "/Users/blacc/miniconda3/lib/python3.9/site-packages/tornado/gen.py", line 769, in run
        yielded = self.gen.throw(*exc_info)  # type: ignore
      File "/Users/blacc/miniconda3/lib/python3.9/site-packages/notebook/services/sessions/handlers.py", line 164, in delete
        yield maybe_future(sm.delete_session(session_id))
      File "/Users/blacc/miniconda3/lib/python3.9/site-packages/tornado/gen.py", line 762, in run
        value = future.result()
      File "/Users/blacc/miniconda3/lib/python3.9/site-packages/tornado/gen.py", line 775, in run
        yielded = self.gen.send(value)
      File "/Users/blacc/miniconda3/lib/python3.9/site-packages/notebook/services/sessions/sessionmanager.py", line 287, in delete_session
        yield maybe_future(self.kernel_manager.shutdown_kernel(session['kernel']['id']))
      File "/Users/blacc/miniconda3/lib/python3.9/site-packages/notebook/services/kernels/kernelmanager.py", line 304, in shutdown_kernel
        self.pinned_superclass.shutdown_kernel(self, kernel_id, now=now, restart=restart)
      File "/Users/blacc/miniconda3/lib/python3.9/site-packages/jupyter_client/utils.py", line 26, in wrapped
        raise e
      File "/Users/blacc/miniconda3/lib/python3.9/site-packages/jupyter_client/utils.py", line 23, in wrapped
        return loop.run_until_complete(future)
      File "/Users/blacc/miniconda3/lib/python3.9/site-packages/nest_asyncio.py", line 89, in run_until_complete
        return f.result()
      File "/Users/blacc/miniconda3/lib/python3.9/asyncio/futures.py", line 201, in result
        raise self._exception
      File "/Users/blacc/miniconda3/lib/python3.9/asyncio/tasks.py", line 256, in __step
        result = coro.send(None)
      File "/Users/blacc/miniconda3/lib/python3.9/site-packages/jupyter_client/multikernelmanager.py", line 274, in _async_shutdown_kernel
        if km.ready.exception():
    asyncio.exceptions.InvalidStateError: Exception is not set.
[W 16:37:31.346 NotebookApp] Unhandled error
[E 16:37:31.346 NotebookApp] {
      "Host": "localhost:8890",
      "Accept": "application/json, text/javascript, */*; q=0.01",
      "Referer": "http://localhost:8890/notebooks/Untitled.ipynb",
      "User-Agent": "Mozilla/5.0 (Macintosh; Intel Mac OS X 10_15_7) AppleWebKit/605.1.15 (KHTML, like Gecko) Version/15.6 Safari/605.1.15"
    }
[E 16:37:31.346 NotebookApp] 500 DELETE /api/sessions/ee6b332e-6aef-4679-b18b-ceae95de25a5 (::1) 2.690000ms referer=http://localhost:8890/notebooks/Untitled.ipynb
[I 16:37:36.929 NotebookApp] Creating new notebook in 
[I 16:37:37.533 NotebookApp] Kernel started: 39f7acf6-61fe-4705-9c67-bcf5a86b5e98, name: python3
[I 16:39:37.555 NotebookApp] Saving file at /computer_vision.ipynb
[I 16:41:37.550 NotebookApp] Saving file at /computer_vision.ipynb
[I 16:43:37.538 NotebookApp] Saving file at /computer_vision.ipynb
[I 16:45:37.537 NotebookApp] Saving file at /computer_vision.ipynb
[I 16:47:37.529 NotebookApp] Saving file at /computer_vision.ipynb
[I 16:49:37.554 NotebookApp] Saving file at /computer_vision.ipynb
[W 16:51:12.373 NotebookApp] Notebook computer_vision.ipynb is not trusted
[I 16:51:37.542 NotebookApp] Saving file at /computer_vision.ipynb
[I 16:53:38.862 NotebookApp] Saving file at /computer_vision.ipynb
[I 16:55:38.877 NotebookApp] Saving file at /computer_vision.ipynb
Metal device set to: Apple M1
2022-07-31 16:57:11.951234: I tensorflow/core/common_runtime/pluggable_device/pluggable_device_factory.cc:305] Could not identify NUMA node of platform GPU ID 0, defaulting to 0. Your kernel may not have been built with NUMA support.
2022-07-31 16:57:11.951722: I tensorflow/core/common_runtime/pluggable_device/pluggable_device_factory.cc:271] Created TensorFlow device (/job:localhost/replica:0/task:0/device:GPU:0 with 0 MB memory) -> physical PluggableDevice (device: 0, name: METAL, pci bus id: <undefined>)
[I 16:57:38.951 NotebookApp] Saving file at /computer_vision.ipynb
[I 16:59:38.971 NotebookApp] Saving file at /computer_vision.ipynb
2022-07-31 17:00:09.968697: W tensorflow/core/platform/profile_utils/cpu_utils.cc:128] Failed to get CPU frequency: 0 Hz
2022-07-31 17:00:55.027442: I tensorflow/core/grappler/optimizers/custom_graph_optimizer_registry.cc:113] Plugin optimizer for device_type GPU is enabled.
[I 17:01:38.990 NotebookApp] Saving file at /computer_vision.ipynb
2022-07-31 17:03:09.628201: I tensorflow/core/grappler/optimizers/custom_graph_optimizer_registry.cc:113] Plugin optimizer for device_type GPU is enabled.
[I 17:03:39.025 NotebookApp] Saving file at /computer_vision.ipynb
[I 17:07:39.060 NotebookApp] Saving file at /computer_vision.ipynb
[I 17:08:41.846 NotebookApp] Kernel interrupted: 39f7acf6-61fe-4705-9c67-bcf5a86b5e98
[I 17:09:33.368 NotebookApp] Kernel interrupted: 39f7acf6-61fe-4705-9c67-bcf5a86b5e98
2022-07-31 17:09:38.818373: I tensorflow/core/grappler/optimizers/custom_graph_optimizer_registry.cc:113] Plugin optimizer for device_type GPU is enabled.
[I 17:09:39.063 NotebookApp] Saving file at /computer_vision.ipynb
[I 17:09:53.932 NotebookApp] Kernel interrupted: 39f7acf6-61fe-4705-9c67-bcf5a86b5e98
[I 17:09:57.761 NotebookApp] Starting buffering for 39f7acf6-61fe-4705-9c67-bcf5a86b5e98:d4bde35fba4943148bf26cfdfd9caa7a
[I 17:10:00.500 NotebookApp] Kernel restarted: 39f7acf6-61fe-4705-9c67-bcf5a86b5e98
[I 17:10:00.512 NotebookApp] Restoring connection for 39f7acf6-61fe-4705-9c67-bcf5a86b5e98:d4bde35fba4943148bf26cfdfd9caa7a
[I 17:10:01.522 NotebookApp] Replaying 3 buffered messages
[I 17:10:26.259 NotebookApp] Starting buffering for 39f7acf6-61fe-4705-9c67-bcf5a86b5e98:d4bde35fba4943148bf26cfdfd9caa7a
[I 17:10:28.906 NotebookApp] Kernel restarted: 39f7acf6-61fe-4705-9c67-bcf5a86b5e98
[I 17:10:28.919 NotebookApp] Restoring connection for 39f7acf6-61fe-4705-9c67-bcf5a86b5e98:d4bde35fba4943148bf26cfdfd9caa7a
[I 17:10:29.419 NotebookApp] Replaying 3 buffered messages
Metal device set to: Apple M1
2022-07-31 17:10:32.472870: I tensorflow/core/common_runtime/pluggable_device/pluggable_device_factory.cc:305] Could not identify NUMA node of platform GPU ID 0, defaulting to 0. Your kernel may not have been built with NUMA support.
2022-07-31 17:10:32.472995: I tensorflow/core/common_runtime/pluggable_device/pluggable_device_factory.cc:271] Created TensorFlow device (/job:localhost/replica:0/task:0/device:GPU:0 with 0 MB memory) -> physical PluggableDevice (device: 0, name: METAL, pci bus id: <undefined>)
2022-07-31 17:10:32.626991: W tensorflow/core/platform/profile_utils/cpu_utils.cc:128] Failed to get CPU frequency: 0 Hz
2022-07-31 17:10:32.946131: I tensorflow/core/grappler/optimizers/custom_graph_optimizer_registry.cc:113] Plugin optimizer for device_type GPU is enabled.
[I 17:11:39.112 NotebookApp] Saving file at /computer_vision.ipynb
2022-07-31 17:12:01.367032: I tensorflow/core/grappler/optimizers/custom_graph_optimizer_registry.cc:113] Plugin optimizer for device_type GPU is enabled.
[I 17:13:39.150 NotebookApp] Saving file at /computer_vision.ipynb
[I 17:14:45.251 NotebookApp] Kernel shutdown: 39f7acf6-61fe-4705-9c67-bcf5a86b5e98
[I 17:14:45.287 NotebookApp] Starting buffering for 39f7acf6-61fe-4705-9c67-bcf5a86b5e98:d4bde35fba4943148bf26cfdfd9caa7a
[I 17:14:45.291 NotebookApp] Kernel shutdown: 39f7acf6-61fe-4705-9c67-bcf5a86b5e98
[E 17:14:45.291 NotebookApp] Uncaught exception DELETE /api/sessions/dc260153-ff73-41c4-962c-5039b9fa8cec (::1)
    HTTPServerRequest(protocol='http', host='localhost:8890', method='DELETE', uri='/api/sessions/dc260153-ff73-41c4-962c-5039b9fa8cec', version='HTTP/1.1', remote_ip='::1')
    Traceback (most recent call last):
      File "/Users/blacc/miniconda3/lib/python3.9/site-packages/tornado/web.py", line 1704, in _execute
        result = await result
      File "/Users/blacc/miniconda3/lib/python3.9/site-packages/tornado/gen.py", line 769, in run
        yielded = self.gen.throw(*exc_info)  # type: ignore
      File "/Users/blacc/miniconda3/lib/python3.9/site-packages/notebook/services/sessions/handlers.py", line 164, in delete
        yield maybe_future(sm.delete_session(session_id))
      File "/Users/blacc/miniconda3/lib/python3.9/site-packages/tornado/gen.py", line 762, in run
        value = future.result()
      File "/Users/blacc/miniconda3/lib/python3.9/site-packages/tornado/gen.py", line 775, in run
        yielded = self.gen.send(value)
      File "/Users/blacc/miniconda3/lib/python3.9/site-packages/notebook/services/sessions/sessionmanager.py", line 287, in delete_session
        yield maybe_future(self.kernel_manager.shutdown_kernel(session['kernel']['id']))
      File "/Users/blacc/miniconda3/lib/python3.9/site-packages/notebook/services/kernels/kernelmanager.py", line 304, in shutdown_kernel
        self.pinned_superclass.shutdown_kernel(self, kernel_id, now=now, restart=restart)
      File "/Users/blacc/miniconda3/lib/python3.9/site-packages/jupyter_client/utils.py", line 26, in wrapped
        raise e
      File "/Users/blacc/miniconda3/lib/python3.9/site-packages/jupyter_client/utils.py", line 23, in wrapped
        return loop.run_until_complete(future)
      File "/Users/blacc/miniconda3/lib/python3.9/site-packages/nest_asyncio.py", line 89, in run_until_complete
        return f.result()
      File "/Users/blacc/miniconda3/lib/python3.9/asyncio/futures.py", line 201, in result
        raise self._exception
      File "/Users/blacc/miniconda3/lib/python3.9/asyncio/tasks.py", line 256, in __step
        result = coro.send(None)
      File "/Users/blacc/miniconda3/lib/python3.9/site-packages/jupyter_client/multikernelmanager.py", line 274, in _async_shutdown_kernel
        if km.ready.exception():
    asyncio.exceptions.InvalidStateError: Exception is not set.
[W 17:14:45.296 NotebookApp] Unhandled error
[E 17:14:45.296 NotebookApp] {
      "Host": "localhost:8890",
      "Accept": "application/json, text/javascript, */*; q=0.01",
      "Referer": "http://localhost:8890/notebooks/computer_vision.ipynb",
      "User-Agent": "Mozilla/5.0 (Macintosh; Intel Mac OS X 10_15_7) AppleWebKit/605.1.15 (KHTML, like Gecko) Version/15.6 Safari/605.1.15"
    }
[E 17:14:45.296 NotebookApp] 500 DELETE /api/sessions/dc260153-ff73-41c4-962c-5039b9fa8cec (::1) 7.130000ms referer=http://localhost:8890/notebooks/computer_vision.ipynb
